Traceback (most recent call last):
  File "D:\openclass\mac_giver\env34\lib\configparser.py", line 823, in items
    d.update(self._sections[section])
KeyError: 'Config'

During handling of the above exception, another exception occurred:

Traceback (most recent call last):
  File "config.py", line 636, in <module>
  File "config.py", line 34, in __init__
  File "D:\openclass\mac_giver\env34\lib\configparser.py", line 826, in items
    raise NoSectionError(section)
configparser.NoSectionError: No section: 'Config'
